Workbook

Sheet RAW_COPY
A1: SUBJECT_ID | B1: Familia_IO
A2: DATE | B2: dd_mm_yyyy
A3: Time | B3: hh:mm:ss
B5: фоновая | F5: после счета | J5: Индексы опроса по шкале Лайкерта_7
B6: ПЗР | F6: ПЗР | J6: SELF_SLEEP_QUALITY | K6: восстановление после сна за последнюю ночь | N6: SELF_SLEEP_QUALITY_DELTA_WEEK
A7: лево | B7: центр | C7: право | E7: лево | F7: центр | G7: право | J7: SELF_APPETITE | K7: аппетит | N7: SELF_APPETITE_DELTA_WEEK
J8: SELF_ENERGY | K8: текущий уровень физической энергии (бодрости, сил) | N8: SELF_ENERGY_DELTA_WEEK
J9: SELF_MOTIVATION | K9: текущее желание тренироваться | N9: SELF_MOTIVATION_DELTA_WEEK
B10: СЗР цвет | F10: СЗР цвет | J10: SELF_MUSCLE_PAIN | K10: текущий уровень неприятных ощущений в мышцах | N10: SELF_MUSCLE_PAIN_DELTA_WEEK
A11: лево | B11: центр | C11: право | E11: лево | F11: центр | G11: право | J11: SELF_FOCUS | K11: способность удерживать концентрацию на технике | N11: SELF_FOCUS_DELTA_WEEK
B14: СЗР сдвиг | F14: СЗР сдвиг
A15: лево | B15: центр | C15: право | E15: лево | F15: центр | G15: право
B18: ВПР цвет | F18: ВПР цвет
A19: лево | B19: центр | C19: право | E19: лево | F19: центр | G19: право
B22: ВПР сдвиг | F22: ВПР сдвиг
A23: лево | B23: центр | C23: право | E23: лево | F23: центр | G23: право
A26: Данные вставляются копированием таблиц
A27: после формирования заключения по текущему тестированию

Sheet INPUT
A1: FIELD | B1: TYPE | C1: SCALE | D1: VALUES | E1: UNIT | F1: VALUE
A3: SUBJECT_ID | B3: string | F3: =RAW_COPY!B1 -> Familia_IO
A4: DATE | B4: string | F4: =RAW_COPY!B2 -> dd_mm_yyyy
A5: Time | B5: string | F5: =RAW_COPY!B3 -> hh:mm:ss
A7: V1_PRE_ALL_MEAN | B7: float | E7: ms | F7: =RAW_COPY!B8 -> 0
A8: V1_PRE_LH_MEAN | B8: float | E8: ms | F8: =RAW_COPY!A9 -> 0
A9: V1_PRE_CENTER_MEAN | B9: float | E9: ms | F9: =RAW_COPY!B9 -> 0
A10: V1_PRE_RH_MEAN | B10: float | E10: ms | F10: =RAW_COPY!C9 -> 0
A12: V4_PRE_ALL_MEAN | B12: float | E12: ms | F12: =RAW_COPY!B12 -> 0
A13: V4_PRE_LH_MEAN | B13: float | E13: ms | F13: =RAW_COPY!A13 -> 0
A14: V4_PRE_CENTER_MEAN | B14: float | E14: ms | F14: =RAW_COPY!B13 -> 0
A15: V4_PRE_RH_MEAN | B15: float | E15: ms | F15: =RAW_COPY!C13 -> 0
A17: V5_PRE_ALL_MEAN | B17: float | E17: ms | F17: =RAW_COPY!B16 -> 0
A18: V5_PRE_LH_MEAN | B18: float | E18: ms | F18: =RAW_COPY!A17 -> 0
A19: V5_PRE_CENTER_MEAN | B19: float | E19: ms | F19: =RAW_COPY!B17 -> 0
A20: V5_PRE_RH_MEAN | B20: float | E20: ms | F20: =RAW_COPY!C17 -> 0
A22: DV4_PRE_ALL_MEAN | B22: float | E22: ms | F22: =RAW_COPY!B20 -> 0
A23: DV4_PRE_LH_MEAN | B23: float | E23: ms | F23: =RAW_COPY!A21 -> 0
A24: DV4_PRE_CENTER_MEAN | B24: float | E24: ms | F24: =RAW_COPY!B21 -> 0
A25: DV4_PRE_RH_MEAN | B25: float | E25: ms | F25: =RAW_COPY!C21 -> 0
A27: DV5_PRE_ALL_MEAN | B27: float | E27: ms | F27: =RAW_COPY!B24 -> 0
A28: DV5_PRE_LH_MEAN | B28: float | E28: ms | F28: =RAW_COPY!A25 -> 0
A29: DV5_PRE_CENTER_MEAN | B29: float | E29: ms | F29: =RAW_COPY!B25 -> 0
A30: DV5_PRE_RH_MEAN | B30: float | E30: ms | F30: =RAW_COPY!C25 -> 0
A32: V1_POST_ALL_MEAN | B32: float | E32: ms | F32: =RAW_COPY!F8 -> 0
A33: V1_POST_LH_MEAN | B33: float | E33: ms | F33: =RAW_COPY!E9 -> 0
A34: V1_POST_CENTER_MEAN | B34: float | E34: ms | F34: =RAW_COPY!F9 -> 0
A35: V1_POST_RH_MEAN | B35: float | E35: ms | F35: =RAW_COPY!G9 -> 0
A37: V4_POST_ALL_MEAN | B37: float | E37: ms | F37: =RAW_COPY!F12 -> 0
A38: V4_POST_LH_MEAN | B38: float | E38: ms | F38: =RAW_COPY!E13 -> 0
A39: V4_POST_CENTER_MEAN | B39: float | E39: ms | F39: =RAW_COPY!F13 -> 0
A40: V4_POST_RH_MEAN | B40: float | E40: ms | F40: =RAW_COPY!G13 -> 0
A42: V5_POST_ALL_MEAN | B42: float | E42: ms | F42: =RAW_COPY!F16 -> 0
A43: V5_POST_LH_MEAN | B43: float | E43: ms | F43: =RAW_COPY!E17 -> 0
A44: V5_POST_CENTER_MEAN | B44: float | E44: ms | F44: =RAW_COPY!F17 -> 0
A45: V5_POST_RH_MEAN | B45: float | E45: ms | F45: =RAW_COPY!G17 -> 0
A47: DV4_POST_ALL_MEAN | B47: float | E47: ms | F47: =RAW_COPY!F20 -> 0
A48: DV4_POST_LH_MEAN | B48: float | E48: ms | F48: =RAW_COPY!E21 -> 0
A49: DV4_POST_CENTER_MEAN | B49: float | E49: ms | F49: =RAW_COPY!F21 -> 0
A50: DV4_POST_RH_MEAN | B50: float | E50: ms | F50: =RAW_COPY!G21 -> 0
...
